Workbook

Sheet BS
A1: Corvus Data Services Private Limited
A2: Balance Sheet as at March 31, 2026
A3: (All amounts in ₹ lakhs, unless otherwise stated)
A5: Particulars | B5: Note | C5: As at March 31, 2026 | D5: As at March 31, 2025
A6: ASSETS
A7: Non-current assets
A8: (a) Property, plant and equipment | B8: 3 | C8: ='Note 3-5'!E27 -> 557.79 | D8: ='Note 3-5'!E26 -> 478.14
A9: (b) Capital work-in-progress | B9: 3 | C9: ='Note 3-5'!B36 -> 10.86 | D9: ='Note 3-5'!B33 -> 8.57
A10: (c) Right-of-use assets | B10: 4 | C10: ='Note 3-5'!B54 -> 177.72 | D10: ='Note 3-5'!B53 -> 199.72
A11: (d) Other intangible assets | B11: 5 | C11: ='Note 3-5'!B72 -> 53.85 | D11: ='Note 3-5'!B71 -> 53.82
A12: (e) Financial assets
A13: (i) Investments | B13: 6 | C13: ='Note 6-11'!B9 -> 282.84 | D13: ='Note 6-11'!C9 -> 250
A14: (ii) Other financial assets | B14: 7 | C14: ='Note 6-11'!B16 -> 53.44 | D14: ='Note 6-11'!C16 -> 46.95
A15: (f) Deferred tax assets (net) | B15: 8 | C15: ='Note 6-11'!B28 -> 52.52 | D15: ='Note 6-11'!C28 -> 43.9
A16: (g) Other non-current assets | B16: 9 | C16: ='Note 6-11'!B34 -> 2.34 | D16: ='Note 6-11'!C34 -> 5.37
A17: Total non-current assets | C17: =SUM(C8:C16) -> 1191.36 | D17: =SUM(D8:D16) -> 1086.47
A18: Current assets
A19: (a) Financial assets
A20: (i) Trade receivables | B20: 10 | C20: ='Note 6-11'!B47 -> 755.82 | D20: ='Note 6-11'!C47 -> 587.08
A21: (ii) Cash and cash equivalents | B21: 11 | C21: ='Note 6-11'!B65 -> 1371.98 | D21: ='Note 6-11'!C65 -> 600.91
A22: (iii) Other financial assets | B22: 7 | C22: ='Note 6-11'!B21 -> 111.91 | D22: ='Note 6-11'!C21 -> 86.87
A23: (b) Other current assets | B23: 9 | C23: ='Note 6-11'!B39 -> 121.23 | D23: ='Note 6-11'!C39 -> 108.21
A24: Total current assets | C24: =SUM(C20:C23) -> 2360.94 | D24: =SUM(D20:D23) -> 1383.07
A25: TOTAL ASSETS | C25: =C17+C24 -> 3552.3 | D25: =D17+D24 -> 2469.54
A27: EQUITY AND LIABILITIES
A28: Equity
A29: (a) Equity share capital | B29: 12 | C29: ='Note 12-13'!B11 -> 1050 | D29: ='Note 12-13'!C11 -> 1000
A30: (b) Other equity | B30: 13 | C30: ='Note 12-13'!B42 -> 700.31 | D30: ='Note 12-13'!C42 -> 250.31
A31: Total equity | C31: =SUM(C29:C30) -> 1750.31 | D31: =SUM(D29:D30) -> 1250.31
A32: Liabilities
A33: Non-current liabilities
A34: (a) Financial liabilities
A35: (i) Borrowings | B35: 14 | C35: ='Note 14-19'!B10 -> 754.24 | D35: ='Note 14-19'!C10 -> 739.93
A36: (ii) Lease liabilities | B36: 15 | C36: ='Note 14-19'!B45 -> 133.5 | D36: ='Note 14-19'!C45 -> 135.59
A37: (b) Provisions | B37: 16 | C37: ='Note 14-19'!B58 -> 161.05 | D37: ='Note 14-19'!C58 -> 125.84
A38: Total non-current liabilities | C38: =SUM(C35:C37) -> 1048.79 | D38: =SUM(D35:D37) -> 1001.36
A39: Current liabilities
A40: (a) Financial liabilities
A41: (i) Borrowings | B41: 14 | C41: ='Note 14-19'!B13 -> 74.79 | D41: ='Note 14-19'!C13 -> 67.82
A42: (ii) Lease liabilities | B42: 15 | C42: ='Note 14-19'!B44 -> 57.21 | D42: ='Note 14-19'!C44 -> 58.11
...

Sheet PL
A1: Corvus Data Services Private Limited
A2: Statement of Profit and Loss for the year ended March 31, 2026
A3: (All amounts in ₹ lakhs, unless otherwise stated)
A5: Particulars | B5: Note | C5: Year ended March 31, 2026 | D5: Year ended March 31, 2025
A6: I. Revenue from operations | B6: 20 | C6: ='Note 20-27'!B9 -> 4468.37 | D6: ='Note 20-27'!C9 -> 3478.37
A7: II. Other income | B7: 21 | C7: ='Note 20-27'!B23 -> 37.29 | D7: ='Note 20-27'!C23 -> 27.1
A8: III. Total income (I + II) | C8: =SUM(C6:C7) -> 4505.66 | D8: =SUM(D6:D7) -> 3505.47
A9: IV. Expenses
A10: Employee benefits expense | B10: 22 | C10: ='Note 20-27'!B31 -> 2644.21 | D10: ='Note 20-27'!C31 -> 2552.97
A11: Finance costs | B11: 23 | C11: ='Note 20-27'!B38 -> 85.13 | D11: ='Note 20-27'!C38 -> 89.99
A12: Depreciation and amortisation expense | B12: 24 | C12: ='Note 20-27'!B45 -> 195.5 | D12: ='Note 20-27'!C45 -> 162.87
A13: Other expenses | B13: 25 | C13: ='Note 20-27'!B57 -> 933.25 | D13: ='Note 20-27'!C57 -> 891.16
A14: Total expenses (IV) | C14: =SUM(C10:C13)-0.01 -> 3858.08 | D14: =SUM(D10:D13) -> 3696.99
A15: V. Profit/(loss) before tax (III – IV) | C15: =C8-C14 -> 647.58 | D15: =D8-D14 -> -191.52
A16: VI. Tax expense | B16: 26
A17: (1) Current tax | C17: ='Note 20-27'!B66 -> 171.14 | D17: ='Note 20-27'!C66 -> 3.56
A18: (2) Deferred tax | C18: ='Note 20-27'!B67 -> -6.16 | D18: ='Note 20-27'!C67 -> -8.22
A19: Total tax expense (VI) | C19: =SUM(C17:C18) -> 164.98 | D19: =SUM(D17:D18) -> -4.66
A20: VII. Profit/(loss) for the year (V – VI) | C20: =C15-C19+C25 -> 475.3 | D20: =D15-D19 -> -186.86
A21: VIII. Other comprehensive income
A22: (A) (i) Items that will not be reclassified to profit or loss
A23: – Remeasurement gains/(losses) on defined benefit plans | C23: =-SUMIF(NS_TB_FT27!$H$5:$H$82,"oci.remeasurement",NS_TB_FT27!$I$5:$I$82)/100000 -> -9.76 | D23: =-SUMIF(NS_TB_FT27!$H$5:$H$82,"oci.remeasurement",NS_TB_FT27!$J$5:$J$82)/100000 -> -6.51
A24: (ii) Income tax relating to items that will not be reclassified to profit or loss | C24: =-SUMIF(NS_TB_FT27!$H$5:$H$82,"oci.tax",NS_TB_FT27!$I$5:$I$82)/100000 -> 2.46 | D24: =-SUMIF(NS_TB_FT27!$H$5:$H$82,"oci.tax",NS_TB_FT27!$J$5:$J$82)/100000 -> 1.64
A25: Total other comprehensive income for the year, net of tax (VIII) | C25: =SUM(C23:C24) -> -7.3 | D25: =SUM(D23:D24) -> -4.87
A26: IX. Total comprehensive income for the year (VII + VIII) | C26: =C20+C25 -> 468 | D26: =D20+D25 -> -191.73
A27: X. Earnings/(loss) per equity share (face value of ₹10 each) | B27: 27
A28: Basic (₹) | C28: ='Note 20-27'!C87 -> -1.8686 | D28: ='Note 20-27'!C87 -> -1.8686
A29: Diluted (₹) | C29: ='Note 20-27'!B87 -> 4.6849719 | D29: ='Note 20-27'!C87 -> -1.8686
A31: The accompanying notes form an integral part of these financial statements.
A33: As per our report of even date | C33: For and on behalf of the Board of Directors of
A34: For Synthetic & Co. | C34: Corvus Data Services Private Limited
A35: Chartered Accountants | C35: CIN: U72900KA2015PTC081234
A36: Firm Registration No.: 123456W
A39: Rohit Mehra | C39: Asha Raman | D39: Vikram Sethi
A40: Partner | C40: Director | D40: Director
A41: Membership No.: 234567 | C41: DIN: 01234567 | D41: DIN: 01234567
A43: Place: Bengaluru | C43: Place: Bengaluru
A44: Date: May 15, 2026 | C44: Date: May 15, 2026

Sheet SOCIE
A1: Corvus Data Services Private Limited
A2: Statement of Changes in Equity for the year ended March 31, 2026
A3: (All amounts in ₹ lakhs, unless otherwise stated)
A5: Equity share capital (refer note 12) and other equity (refer note 13)
A6: Particulars | B6: Equity share capital | C6: Securities premium | D6: Retained earnings | E6: Total equity
A7: Balance as at April 1, 2024 | B7: 1000 | C7: 1500 | D7: -1526.12 | E7: =SUM(B7:D7) -> 973.88
A8: Profit/(loss) for the year | D8: -186.88 | E8: =SUM(B8:D8) -> -186.88
A9: Other comprehensive income for the year, net of tax | D9: =PL!D25 -> -4.87 | E9: =SUM(B9:D9) -> -4.87
A10: Total comprehensive income for the year | B10: =SUM(B8:B9) -> 0 | C10: =SUM(C8:C9) -> 0 | D10: =SUM(D8:D9) -> -191.75 | E10: =SUM(E8:E9) -> -191.75
A11: Issue of equity shares | B11: 0 | C11: 0 | E11: =SUM(B11:D11) -> 0
A12: Balance as at March 31, 2025 | B12: =B7+B10+B11 -> 1000 | C12: =C7+C10+C11 -> 1500 | D12: =D7+D10+D11 -> -1717.87 | E12: =E7+E10+E11 -> 782.13
A13: Profit/(loss) for the year | D13: =PL!C20 -> 475.3 | E13: =SUM(B13:D13) -> 475.3
A14: Other comprehensive income for the year, net of tax | D14: =PL!C25 -> -7.3 | E14: =SUM(B14:D14) -> -7.3
A15: Total comprehensive income for the year | B15: =SUM(B13:B14) -> 0 | C15: =SUM(C13:C14) -> 0 | D15: =SUM(D13:D14) -> 468 | E15: =SUM(E13:E14) -> 468
A16: Issue of equity shares | B16: ='Note 12-13'!C17 -> 50 | C16: ='Note 12-13'!B35 -> 450 | E16: =SUM(B16:D16) -> 500
A17: Balance as at March 31, 2026 | B17: =B12+B15+B16 -> 1050 | C17: =C12+C15+C16 -> 1950 | D17: =D12+D15+D16 -> -1249.87 | E17: =E12+E15+E16 -> 1750.13
A19: The accompanying notes form an integral part of these financial statements.
A21: As per our report of even date | C21: For and on behalf of the Board of Directors of
A22: For Synthetic & Co. | C22: Corvus Data Services Private Limited
A23: Chartered Accountants | C23: CIN: U72900KA2015PTC081234
A24: Firm Registration No.: 123456W
A27: Rohit Mehra | C27: Asha Raman | D27: Vikram Sethi
A28: Partner | C28: Director | D28: Directer
A29: Membership No.: 234567 | C29: DIN: 01234567 | D29: DIN: 07654321
A31: Place: Bengaluru | C31: Place: Bengaluru
A32: Date: May 15, 2026 | C32: Date: March 15, 2026

Sheet CFS
A1: Corvus Data Services Private Limited
A2: Cash Flow Statement for the year ended March 31, 2026
A3: (All amounts in ₹ lakhs, unless otherwise stated)
A5: Particulars | B5: Year ended March 31, 2026 | C5: Year ended March 31, 2025
A6: A. Cash flow from operating activities
A7: Profit/(loss) before tax | B7: =PL!C15 -> 647.58 | C7: =PL!D15 -> -191.52
A8: Adjustments for:
A9: Depreciation and amortisation expense | B9: 195.53 | C9: =PL!D12 -> 162.87
A10: Finance costs | B10: =PL!C11 -> 85.13 | C10: =PL!D11 -> 89.99
A11: Interest income | B11: =-'Note 20-27'!B21 -> -29.57 | C11: =-'Note 20-27'!C21 -> -21.25
A12: Operating profit/(loss) before working capital changes | B12: =SUM(B7:B11) -> 898.67 | C12: =SUM(C7:C11) -> 40.09
A13: Changes in working capital:
A14: (Increase)/decrease in trade receivables | B14: =BS!D20-BS!C20 -> -168.74 | C14: 371.27
A15: (Increase)/decrease in other financial assets | B15: =(BS!D14+BS!D22)-(BS!C14+BS!C22) -> -31.53 | C15: -13.98
A16: (Increase)/decrease in other assets | B16: =(BS!D16+BS!D23)-(BS!C16+BS!C23) -> -9.99 | C16: -14.32
A17: Increase/(decrease) in trade payables | B17: =(BS!C44+BS!C45)-(BS!D44+BS!D45) -> 8.39 | C17: -24.71
A18: Increase/(decrease) in other financial liabilities | B18: =BS!C46-BS!D46 -> 2.99 | C18: 7.23
A19: (Decrease)/increase in other current liabilities | B19: =BS!C47-BS!D47 -> 8.062 | C19: 10.19
A20: Increase/(decrease) in provisions | B20: =(BS!C37+BS!C48)-(BS!D37+BS!D48) -> 48.84 | C20: 43.38
A21: Remeasurement of defined benefit plans (recognised in other comprehensive income) | B21: =PL!C23 -> -9.76 | C21: -6.51
A22: Cash generated from/(used in) operations | B22: =SUM(B12:B21) -> 746.932 | C22: =SUM(C12:C21) -> 412.64
A23: Income taxes paid (net of refunds) | B23: =-(PL!C17-(BS!C49-BS!D49)) -> -151.03 | C23: -22.55
A24: Net cash generated from/(used in) operating activities (A) | B24: =SUM(B22:B23)-0.03 -> 595.872 | C24: =SUM(C22:C23) -> 390.09
A26: B. Cash flow from investing activities
A27: Purchase of property, plant and equipment (including capital work-in-progress) | B27: =-('Note 3-5'!E14+'Note 3-5'!B34+'Note 3-5'!B35) -> -199.96 | C27: -184.75
A28: Proceeds from sale of property, plant and equipment | B28: =-'Note 3-5'!E15+'Note 3-5'!E23 -> 8.46 | C28: 6.7
A29: Proceeds from sale of intangible assets | B29: =-'Note 3-5'!B62 -> -21.44 | C29: -19.09
A30: Investment in subsidiary | B30: =-(BS!C13-BS!D13)-0.47 -> -33.31 | C30: 0
A31: Interest received | B31: ='Note 20-27'!B21 -> 29.57 | C31: 21.25
A32: Net cash generated from/(used in) investing activities (B) | B32: =SUM(B27:B31) -> -216.68 | C32: =SUM(C27:C31) -> -175.89
A34: C. Cash flow from financing activities
A35: Proceeds from issue of equity shares (including securities premium) | B35: ='Note 12-13'!C17+'Note 12-13'!B35 -> 500 | C35: 0
A36: Proceeds from long-term borrowings | B36: ='Note 14-19'!B29+'Note 14-19'!C29 -> 95.69 | C36: 97.17
A37: Repayment of long-term borrowings | B37: ='Note 14-19'!B30+'Note 14-19'!C30 -> -113.02 | C37: -104.17
A38: Payment of principal portion of lease liabilities | B38: ='Note 14-19'!B41+'Note 14-19'!B40 -> -45.52 | C38: -59.5
A39: Payment of interest portion of lease liabilities | B39: =-'Note 14-19'!B40 -> -16.46 | C39: -21.52
A40: Interest paid on borrowings | B40: =-('Note 20-27'!B35+'Note 20-27'!B36-'Note 14-19'!C31) -> -30.06 | C40: -38.95
A41: Net cash generated from/(used in) financing activities (C) | B41: =SUM(B35:B40) -> 390.63 | C41: =SUM(C35:C40) -> -126.97
A43: Net increase/(decrease) in cash and cash equivalents (A + B + C) | B43: =B24+B32+B41 -> 769.822 | C43: =C24+C32+C41 -> 87.23
A44: Cash and cash equivalents at the beginning of the year | B44: =C45 -> 600.95 | C44: 513.71
...

Sheet Policies
A1: Corvus Data Services Private Limited
A2: Notes to the financial statements for the year ended March 31, 2026
A3: (All amounts in ₹ lakhs, unless otherwise stated)
A5: 1. Corporate information
A6: Corvus Data Services Private Limited ("the Company") is a private limited company incorporated in India under the Companies Act, 2013 (CIN: U72900KA2015PTC081234). Its registered office is at 4th Floor, Synthetic Tech Park, Outer Ring Road, Bengaluru 560103, Karnataka. The Company provides data engineering, analytics and software support services to customers in India and overseas, including group companies. The Company is a subsidiary of Corvus Holdings Private Limited.
A8: 2. Basis of preparation and material accounting policy information
A9: 2.1 Statement of compliance – These financial statements have been prepared in accordance with the Indian Accounting Standards (Ind AS) notified under section 133 of the Companies Act, 2013 read with the Companies (Indian Accounting Standards) Rules, 2015, as amended, and the presentation requirements of Division II of Schedule III to the Act.
A10: 2.2 Basis of measurement – The financial statements have been prepared on the historical cost basis, except for the net defined benefit liability, which is measured at the present value of the defined benefit obligation.
A11: 2.3 Functional and presentation currency – The functional currency of the Company is the Indian Rupee. All amounts are presented in ₹ lakhs with two decimals, unless otherwise stated; totals are computed on the presented figures.
A12: 2.4 Use of estimates and judgements – Estimates and underlying assumptions are reviewed on an ongoing basis. Significant estimates relate to useful lives of property, plant and equipment, expected credit losses on receivables, the defined benefit obligation and recognition of deferred tax assets.
A13: 2.5 Revenue recognition – Revenue from services is recognised over time as the services are rendered, at the transaction price allocated to the performance obligation, in accordance with Ind AS 115.
A14: 2.6 Property, plant and equipment – Items are stated at cost less accumulated depreciation and impairment. Depreciation is provided on the straight-line method over the useful lives prescribed in Schedule II to the Act.
... A19: 2.11 Going concern – Refer note 29.

Sheet Note 3-5
A1: Corvus Data Services Private Limited
A2: Notes to the financial statements for the year ended March 31, 2026
A3: (All amounts in ₹ lakhs, unless otherwise stated)
A5: 3. Property, plant and equipment and capital work-in-progress
A6: (a) Property, plant and equipment
A7: Particulars | B7: Computers | C7: Furniture and fixtures | D7: Office equipment | E7: Total
A8: Gross carrying amount
A9: Balance as at April 1, 2024 | B9: =FAR!B6/100000 -> 397.8 | C9: =FAR!B7/100000 -> 161.15 | D9: =FAR!B8/100000 -> 94.08 | E9: =SUM(B9:D9) -> 653.03
A10: Additions | B10: =FAR!C6/100000 -> 141.88 | C10: =FAR!C7/100000 -> 27.01 | D10: =FAR!C8/100000 -> 17.7 | E10: =SUM(B10:D10) -> 186.59
A11: Disposals | B11: =-FAR!D6/100000 -> -15.91 | C11: =-FAR!D7/100000 -> -6.45 | D11: =-FAR!D8/100000 -> 0 | E11: =SUM(B11:D11) -> -22.36
A12: Balance as at March 31, 2025 | B12: =SUM(B9:B11) -> 523.77 | C12: =SUM(C9:C11) -> 181.71 | D12: =SUM(D9:D11) -> 111.78 | E12: =SUM(E9:E11) -> 817.26
A13: Balance as at June 30, 2025 | B13: =B12 -> 523.77 | C13: =C12 -> 181.71 | D13: =D12 -> 111.78 | E13: =SUM(B13:D13) -> 817.26
A14: Additions | B14: =FAR!C12/100000 -> 143.27 | C14: =FAR!C13/100000 -> 34.95 | D14: =FAR!C14/100000 -> 19.46 | E14: 197.67
A15: Disposals | B15: =-FAR!D12/100000 -> -20.95 | C15: =-FAR!D13/100000 -> -7.27 | D15: =-FAR!D14/100000 -> 0 | E15: =SUM(B15:D15) -> -28.22
A16: Balance as at March 31, 2026 | B16: =SUM(B13:B15) -> 646.09 | C16: =SUM(C13:C15) -> 209.39 | D16: =SUM(D13:D15) -> 131.24 | E16: =SUM(E13:E15) -> 986.71
A17: Accumulated depreciation
A18: Balance as at April 1, 2024 | B18: =FAR!F6/100000 -> 183.06 | C18: =FAR!F7/100000 -> 50.54 | D18: =FAR!F8/100000 -> 33.59 | E18: =SUM(B18:D18) -> 267.19
A19: Charge for the year | B19: =FAR!G6/100000 -> 68.57 | C19: =FAR!G7/100000 -> 8.73 | D19: =FAR!G8/100000 -> 10.29 | E19: =SUM(B19:D19) -> 87.59
A20: Disposals | B20: =-FAR!H6/100000 -> -11.14 | C20: =-FAR!H7/100000 -> -4.52 | D20: =-FAR!H8/100000 -> 0 | E20: =SUM(B20:D20) -> -15.66
A21: Balance as at March 31, 2025 | B21: =SUM(B18:B20) -> 240.49 | C21: =SUM(C18:C20) -> 54.75 | D21: =SUM(D18:D20) -> 43.88 | E21: =SUM(E18:E20) -> 339.12
A22: Charge for the year | B22: =FAR!G12/100000 -> 87.45 | C22: =FAR!G13/100000 -> 9.96 | D22: =FAR!G14/100000 -> 12.15 | E22: =SUM(B22:D22) -> 109.56
A23: Disposals | B23: =-FAR!H12/100000 -> -14.67 | C23: =-FAR!H13/100000 -> -5.09 | D23: =-FAR!H14/100000 -> 0 | E23: =SUM(B23:D23) -> -19.76
A24: Balance as at March 31, 2026 | B24: =SUM(B21:B23) -> 313.27 | C24: =SUM(C21:C23) -> 59.62 | D24: =SUM(D21:D23) -> 56.03 | E24: =SUM(E21:E23) -> 428.92
A25: Net carrying amount
A26: As at March 31, 2025 | B26: =B12-B21 -> 283.28 | C26: =C12-C21 -> 126.96 | D26: =D12-D21 -> 67.9 | E26: =E12-E21 -> 478.14
A27: As at March 31, 2026 | B27: =B16-B24 -> 332.82 | C27: =C16-C24 -> 149.77 | D27: =D16-D24 -> 75.21 | E27: =E16-E24 -> 557.79
A29: (b) Capital work-in-progress
A30: Balance as at April 1, 2024 | B30: =FAR!B26/100000 -> 10.41
A31: Additions | B31: =FAR!C26/100000 -> 21.42
A32: Capitalised during the year | B32: =-FAR!D26/100000 -> -23.26
A33: Balance as at March 31, 2025 | B33: =SUM(B30:B32) -> 8.57
A34: Additions | B34: =FAR!C27/100000 -> 27.15
A35: Capitalised during the year | B35: =-FAR!D27/100000 -> -24.86
A36: Additions | B36: =SUM(B33:B35) -> 10.86
A38: 4. Right-of-use assets
A39: Particulars | B39: Buildings
A40: Gross carrying amount
A41: Balance as at April 1, 2024 | B41: =FAR!B18/100000 -> 360.8
A42: Additions | B42: =FAR!C18/100000 -> 0
A43: Balance as at March 31, 2025 | B43: =SUM(B41:B42) -> 360.8
...

Sheet Note 6-11
A1: Corvus Data Services Private Limited
A2: Notes to the financial statements for the year ended March 31, 2026
A3: (All amounts in ₹ lakhs, unless otherwise stated)
A5: 6. Investments (non-current)
A6: Particulars | B6: As at March 31, 2026 | C6: As at March 31, 2025
A7: Unquoted equity instruments of subsidiary – at cost
A8: Equity shares of Corvus Data Services FZ-LLC | B8: =SUMIF(NS_TB_FT27!$H$5:$H$82,"inv.nc.subsidiary",NS_TB_FT27!$I$5:$I$82)/100000 -> 282.84 | C8: =SUMIF(NS_TB_FT27!$H$5:$H$82,"inv.nc.subsidiary",NS_TB_FT27!$J$5:$J$82)/100000 -> 250
A9: Total non-current investments | B9: =B8 -> 282.84 | C9: =C8 -> 250
A10: Aggregate amount of unquoted investments | B10: =B9 -> 282.84 | C10: =C9 -> 250
A12: 7. Other financial assets
A13: Particulars | B13: As at March 31, 2026 | C13: As at March 31, 2025
A14: (b) Non-current
A15: Security deposits | B15: =SUMIF(NS_TB_FT27!$H$5:$H$82,"ofa.nc.security_deposits",NS_TB_FT27!$I$5:$I$82)/100000 -> 53.44 | C15: =SUMIF(NS_TB_FT27!$H$5:$H$82,"ofa.nc.security_deposits",NS_TB_FT27!$J$5:$J$82)/100000 -> 46.95
A16: Total | B16: =B15 -> 53.44 | C16: =C15 -> 46.95
A17: (b) Current | B17: 0.43
A18: Interest accrued on deposits | B18: =SUMIF(NS_TB_FT27!$H$5:$H$82,"ofa.c.interest_accrued",NS_TB_FT27!$I$5:$I$82)/100000 -> 0 | C18: =SUMIF(NS_TB_FT27!$H$5:$H$82,"ofa.c.interest_accrued",NS_TB_FT27!$J$5:$J$82)/100000 -> 0
A19: Unbilled revenue | B19: =SUMIF(NS_TB_FT27!$H$5:$H$82,"ofa.c.unbilled",NS_TB_FT27!$I$5:$I$82)/100000 -> 80.48 | C19: =SUMIF(NS_TB_FT27!$H$5:$H$82,"ofa.c.unbilled",NS_TB_FT27!$J$5:$J$82)/100000 -> 61.77
A20: Recoverable from group companies (refer note 28) | B20: =SUMIF(NS_TB_FT27!$H$5:$H$82,"ofa.c.recoverable_group",NS_TB_FT27!$I$5:$I$82)/100000 -> 31 | C20: =SUMIF(NS_TB_FT27!$H$5:$H$82,"ofa.c.recoverable_group",NS_TB_FT27!$J$5:$J$82)/100000 -> 25.1
A21: Total | B21: =SUM(B17:B20) -> 111.91 | C21: =SUM(C18:C20) -> 86.87
A23: 8. Deferred tax assets (net)
A24: Particulars | B24: Year ended March 31, 2026 | C24: Year ended March 31, 2025
A25: Balance at the beginning of the year | B25: =SUMIF(NS_TB_FT27!$H$5:$H$82,"dta",NS_TB_FT27!$J$5:$J$82)/100000 -> 43.9 | C25: 34.04
A26: Credit/(charge) recognised in the statement of profit and loss | B26: =-SUMIF(NS_TB_FT27!$H$5:$H$82,"tax.deferred",NS_TB_FT27!$I$5:$I$82)/100000 -> 6.16 | C26: =-SUMIF(NS_TB_FT27!$H$5:$H$82,"tax.deferred",NS_TB_FT27!$J$5:$J$82)/100000 -> 8.22
A27: Credit/(charge) recognised in other comprehensive income | B27: =SUMIF(NS_TB_FT27!$H$5:$H$82,"oci.tax",NS_TB_FT27!$I$5:$I$82)/100000 -> -2.46 | C27: =SUMIF(NS_TB_FT27!$H$5:$H$82,"oci.tax",NS_TB_FT27!$J$5:$J$82)/100000 -> -1.64
A28: Balance at the end of the year | B28: =SUMIF(NS_TB_FT27!$H$5:$H$82,"dta",NS_TB_FT27!$I$5:$I$82)/100000 -> 52.52 | C28: =SUMIF(NS_TB_FT27!$H$5:$H$82,"dta",NS_TB_FT27!$J$5:$J$82)/100000 -> 43.9
A30: 9. Other assets
A31: Particulars | B31: As at March 31, 2026 | C31: As at March 31, 2025
A32: (a) Non-current
A33: Capital advances | B33: 2.34 | C33: =SUMIF(NS_TB_FT27!$H$5:$H$82,"onca.capital_advances",NS_TB_FT27!$J$5:$J$82)/100000 -> 5.37
A34: Total | B34: =B33 -> 2.34 | C34: =C33 -> 5.37
A35: (b) Current
A36: Prepaid expenses | B36: =SUMIF(NS_TB_FT27!$H$5:$H$82,"oca.prepaid",NS_TB_FT27!$I$5:$I$82)/100000 -> 37.7 | C36: =SUMIF(NS_TB_FT27!$H$5:$H$82,"oca.prepaid",NS_TB_FT27!$J$5:$J$82)/100000 -> 35.1
A37: Balances with government authorities | B37: =SUMIF(NS_TB_FT27!$H$5:$H$82,"oca.govt_balances",NS_TB_FT27!$I$5:$I$82)/100000 -> 80.14 | C37: =SUMIF(NS_TB_FT27!$H$5:$H$82,"oca.govt_balances",NS_TB_FT27!$J$5:$J$82)/100000 -> 65.23
A38: Advances to suppliers | B38: =SUMIF(NS_TB_FT27!$H$5:$H$82,"oca.advances_suppliers",NS_TB_FT27!$I$5:$I$82)/100000 -> 3.39 | C38: =SUMIF(NS_TB_FT27!$H$5:$H$82,"oca.advances_suppliers",NS_TB_FT27!$J$5:$J$82)/100000 -> 7.88
A39: Total | B39: =SUM(B36:B38) -> 121.23 | C39: =SUM(C36:C38) -> 108.21
A41: 10. Trade receivables
A42: Particulars | B42: As at March 31, 2026 | C42: As at March 31, 2025
A43: Unsecured, considered good | B43: =(SUMIF(NS_TB_FT27!$H$5:$H$82,"tr.good.third_party",NS_TB_FT27!$I$5:$I$82)+SUMIF(NS_TB_FT27!$H$5:$H$82,"tr.good.related",NS_TB_FT27!$I$5:$I$82))/100000 -> 754.95 | C43: =(SUMIF(NS_TB_FT27!$H$5:$H$82,"tr.good.third_party",NS_TB_FT27!$J$5:$J$82)+SUMIF(NS_TB_FT27!$H$5:$H$82,"tr.good.related",NS_TB_FT27!$J$5:$J$82))/100000 -> 586.21
A44: Credit impaired | B44: =SUMIF(NS_TB_FT27!$H$5:$H$82,"tr.impaired",NS_TB_FT27!$I$5:$I$82)/100000 -> 33.08 | C44: =SUMIF(NS_TB_FT27!$H$5:$H$82,"tr.impaired",NS_TB_FT27!$J$5:$J$82)/100000 -> 24.38
A45: Total | B45: =SUM(B43:B44) -> 788.03 | C45: =SUM(C43:C44) -> 610.59
...

Sheet Note 12-13
A1: Corvus Data Services Private Limited
A2: Notes to the financial statements for the year ended March 31, 2026
A3: (All amounts in ₹ lakhs, unless otherwise stated)
A5: 12. Equity share capital
A6: Particulars | B6: As at March 31, 2026 | C6: As at March 31, 2025
A7: Authorised
A8: 20,000,000 (as at March 31, 2025: 20,000,000) equity shares of ₹10 each | B8: 2000 | C8: 2000
A9: Issued, subscribed and fully paid-up
A10: 10,500,000 (as at March 31, 2025: 10,000,000) equity shares of ₹10 each | B10: =-SUMIF(NS_TB_FT27!$H$5:$H$82,"eq.share_capital",NS_TB_FT27!$I$5:$I$82)/100000 -> 1050 | C10: =-SUMIF(NS_TB_FT27!$H$5:$H$82,"eq.share_capital",NS_TB_FT27!$J$5:$J$82)/100000 -> 1000
A11: Total equity share capital | B11: =B10 -> 1050 | C11: =C10 -> 1000
A13: (a) Reconciliation of the number of shares and amount outstanding
A14: Particulars | B14: Number of shares March 31, 2026 | C14: Amount March 31, 2026 | D14: Number of shares March 31, 2025 | E14: Amount March 31, 2025
A15: At the beginning of the year | B15: 10000000 | C15: =B15*10/100000 -> 1000 | D15: 10000000 | E15: =D15*10/100000 -> 1000
A16: Balance as at June 30, 2025 | B16: =B15 -> 10000000 | C16: =B16*10/100000 -> 1000 | D16: =D15 -> 10000000 | E16: =D16*10/100000 -> 1000
A17: Issued during the year | B17: 500000 | C17: =B17*10/100000 -> 50 | D17: 0 | E17: =D17*10/100000 -> 0
A18: At the end of the year | B18: =SUM(B15:B17) -> 20500000 | C18: =B18*10/100000 -> 2050 | D18: =SUM(D15:D17) -> 20000000 | E18: =D18*10/100000 -> 2000
A20: (b) Rights, preferences and restrictions attached to equity shares
A21: The Company has one class of equity shares having a par value of ₹10 per share. Each holder of equity shares is entitled to one vote per share and to dividends in proportion to the shares held.
A23: (c) Shares held by the holding company and shareholders holding more than 5% of the shares
A24: Name of the shareholder | B24: Number of shares March 31, 2026 | C24: % holding | D24: Number of shares March 31, 2025 | E24: % holding
A25: Corvus Holdings Private Limited | B25: 10499999 | C25: =B25/B18 -> 0.51219507 | D25: 9999999 | E25: =D25/D18 -> 0.49999995
A27: (d) Shares held by promoters at the end of the year
A28: Promoter name | B28: Number of shares | C28: % of total shares | D28: % change during the year
A29: Corvus Holdings Private Limited | B29: =B25 -> 10499999 | C29: 0.995 | D29: =C29-E25 -> 0.49500005
A31: 13. Other equity
A32: Particulars | B32: Year ended March 31, 2026 | C32: Year ended March 31, 2025
A33: Securities premium
A34: Balance at the beginning of the year | B34: =C36 -> 1499.84 | C34: 1500
A35: Add: Premium on shares issued during the year | B35: 450 | C35: 0
A36: Balance at the end of the year | B36: =SUM(B34:B35) -> 1949.84 | C36: =SUM(C34:C35)-0.16 -> 1499.84
A37: Retained earnings
A38: Balance at the beginning of the year | B38: =-SUMIF(NS_TB_FT27!$H$5:$H$82,"oe.retained_earnings",NS_TB_FT27!$I$5:$I$82)/100000 -> -1717.53 | C38: =-SUMIF(NS_TB_FT27!$H$5:$H$82,"oe.retained_earnings",NS_TB_FT27!$J$5:$J$82)/100000 -> -1526.12
A39: Profit/(loss) for the year | B39: =PL!C20 -> 475.3 | C39: =PL!D20 -> -186.86
A40: Other comprehensive income for the year (net of tax) | B40: =PL!C25 -> -7.3 | C40: =PL!D25 -> -4.87
A41: Balance at the end of the year | B41: =SUM(B38:B40) -> -1249.53 | C41: =SUM(B38:B40) -> -1249.53
A42: Total other equity | B42: =B36+B41 -> 700.31 | C42: =C36+C41 -> 250.31

Sheet Note 14-19
A1: Corvus Data Services Private Limited
A2: Notes to the financial statements for the year ended March 31, 2026
A3: (All amounts in ₹ lakhs, unless otherwise stated)
A5: 14. Borrowings
A6: Particulars | B6: As at March 31, 2026 | C6: As at March 31, 2025 | F6: As at December 31, 2025
A7: (a) Non-current borrowings
A8: Secured – term loan from bank | B8: =-SUMIF(NS_TB_FT27!$H$5:$H$82,"borr.nc.term_loan_bank",NS_TB_FT27!$I$5:$I$82)/100000 -> 224.35 | C8: =-SUMIF(NS_TB_FT27!$H$5:$H$82,"borr.nc.term_loan_bank",NS_TB_FT27!$J$5:$J$82)/100000 -> 203.45 | F8: 208.65
A9: Unsecured – loan from holding company (refer note 28) | B9: =-SUMIF(NS_TB_FT27!$H$5:$H$82,"borr.nc.loan_holding",NS_TB_FT27!$I$5:$I$82)/100000 -> 529.89 | C9: =-SUMIF(NS_TB_FT27!$H$5:$H$82,"borr.nc.loan_holding",NS_TB_FT27!$J$5:$J$82)/100000 -> 536.48 | F9: 492.8
A10: Total non-current borrowings | B10: =SUM(B8:B9) -> 754.24 | C10: =SUM(C8:C9) -> 739.93 | F10: 701.44
A11: (b) Current borrowings
A12: Current maturities of long-term borrowings | B12: =-SUMIF(NS_TB_FT27!$H$5:$H$82,"borr.c.current_maturities",NS_TB_FT27!$I$5:$I$82)/100000 -> 74.79 | C12: =-SUMIF(NS_TB_FT27!$H$5:$H$82,"borr.c.current_maturities",NS_TB_FT27!$J$5:$J$82)/100000 -> 67.82
A13: Total current borrowings | B13: =B12 -> 74.79 | C13: =C12 -> 67.82
A14: (c) Terms of repayment and security
A15: The term loan from bank carries interest at 9.50% p.a., is repayable in quarterly instalments and is secured by hypothecation of the Company's current assets and movable property, plant and equipment.
A16: The loan from the holding company is unsecured and carries interest at 8.00% p.a.; interest is credited to the loan account net of tax deducted at source.
A18: (d) Changes in liabilities arising from financing activities (Ind AS 7)
A19: Particulars | B19: Term loan from bank | C19: Loan from holding company | D19: Lease liabilities | E19: Total
A20: Year ended March 31, 2025
A21: Balance at the beginning of the year | B21: 375.44 | C21: 409.79 | D21: 253.2 | E21: =SUM(B21:D21) -> 1038.43
A22: Cash flows – proceeds | B22: 0 | C22: 97.17 | D22: 0 | E22: =SUM(B22:D22) -> 97.17
A23: Cash flows – repayments / lease payments | B23: -104.17 | C23: 0 | D23: -81.02 | E23: =SUM(B23:D23) -> -185.19
A24: Non-cash – interest credited (net of TDS) / interest accrued | B24: 0 | C24: 29.52 | D24: 21.52 | E24: =SUM(B24:D24) -> 51.04
A25: Non-cash – new leases | B25: 0 | C25: 0 | D25: 0 | E25: =SUM(B25:D25) -> 0
A26: Balance at the end of the year | B26: =SUM(B21:B25) -> 271.27 | C26: =SUM(C21:C25) -> 536.48 | D26: =SUM(D21:D25) -> 193.7 | E26: =SUM(E21:E25) -> 1001.45
A27: Year ended March 31, 2026
A28: Balance at the beginning of the year | B28: 271.27 | C28: 536.48 | D28: 193.7 | E28: =SUM(B28:D28) -> 1001.45
A29: Cash flows – proceeds | B29: 95.69 | C29: 0 | D29: 0 | E29: =SUM(B29:D29) -> 95.69
A30: Cash flows – repayments / lease payments | B30: -67.82 | C30: -45.2 | D30: -61.98 | E30: =SUM(B30:D30) -> -175
A31: Non-cash – interest credited (net of TDS) / interest accrued | B31: 0 | C31: 38.61 | D31: 16.46 | E31: =SUM(B31:D31) -> 55.07
A32: Non-cash – new leases | B32: 0 | C32: 0 | D32: 42.53 | E32: =SUM(B32:D32) -> 42.53
A33: Balance at the end of the year | B33: =SUM(B28:B32) -> 299.14 | C33: =SUM(C28:C32) -> 529.89 | D33: =SUM(D28:D32) -> 190.71 | E33: =SUM(E28:E32) -> 1019.74
A35: 15. Lease liabilities
A36: (a) Movement in lease liabilities
A37: Particulars | B37: Year ended March 31, 2026 | C37: Year ended March 31, 2025
A38: Balance at the beginning of the year | B38: =-(SUMIF(NS_TB_FT27!$H$5:$H$82,"lease.nc",NS_TB_FT27!$J$5:$J$82)+SUMIF(NS_TB_FT27!$H$5:$H$82,"lease.c",NS_TB_FT27!$J$5:$J$82))/100000 -> 193.7 | C38: 253.2
A39: Additions | B39: 42.53 | C39: 0
A40: Finance cost accrued during the year | B40: =SUMIF(NS_TB_FT27!$H$5:$H$82,"fin.interest_lease",NS_TB_FT27!$I$5:$I$82)/100000 -> 16.46 | C40: =SUMIF(NS_TB_FT27!$H$5:$H$82,"fin.interest_lease",NS_TB_FT27!$J$5:$J$82)/100000 -> 21.52
A41: Payment of lease liabilities | B41: -61.98 | C41: -81.02
A42: Balance at the end of the year | B42: =B38+B40+B41 -> 148.18 | C42: =SUM(C38:C41) -> 193.7
A43: (b) Current and non-current classification
...

Sheet Note 20-27
A1: Corvus Data Services Private Limited
A2: Notes to the financial statements for the year ended March 31, 2026
A3: (All amounts in ₹ lakhs, unless otherwise stated)
A5: 20. Revenue from operations
A6: Particulars | B6: Year ended March 31, 2026 | C6: Year ended March 31, 2025
A7: Sale of services | B7: =-(SUMIF(NS_TB_FT27!$H$5:$H$82,"rev.services_domestic",NS_TB_FT27!$I$5:$I$82)+SUMIF(NS_TB_FT27!$H$5:$H$82,"rev.services_export",NS_TB_FT27!$I$5:$I$82))/100000 -> 3438.1 | C7: =-(SUMIF(NS_TB_FT27!$H$5:$H$82,"rev.services_domestic",NS_TB_FT27!$J$5:$J$82)+SUMIF(NS_TB_FT27!$H$5:$H$82,"rev.services_export",NS_TB_FT27!$J$5:$J$82))/100000 -> 2730.19
A8: Support services to group companies (refer note 28) | B8: =-SUMIF(NS_TB_FT27!$H$5:$H$82,"rev.related_support",NS_TB_FT27!$I$5:$I$82)/100000 -> 1030.27 | C8: =-SUMIF(NS_TB_FT27!$H$5:$H$82,"rev.related_support",NS_TB_FT27!$J$5:$J$82)/100000 -> 748.18
A9: Total revenue from operations | B9: =SUM(B7:B8) -> 4468.37 | C9: =SUM(C7:C8) -> 3478.37
A10: (a) Disaggregation of revenue from contracts with customers – by geography
A11: India | B11: =-SUMIF(NS_TB_FT27!$H$5:$H$82,"rev.services_domestic",NS_TB_FT27!$I$5:$I$82)/100000 -> 2098.52 | C11: =-SUMIF(NS_TB_FT27!$H$5:$H$82,"rev.services_domestic",NS_TB_FT27!$J$5:$J$82)/100000 -> 1617.65
A12: Outside India | B12: =-SUMIF(NS_TB_FT27!$H$5:$H$82,"rev.services_export",NS_TB_FT27!$I$5:$I$82)/100000 -> 1339.58 | C12: =-(SUMIF(NS_TB_FT27!$H$5:$H$82,"rev.services_export",NS_TB_FT27!$J$5:$J$82)+SUMIF(NS_TB_FT27!$H$5:$H$82,"rev.related_support",NS_TB_FT27!$J$5:$J$82))/100000 -> 1860.72
A13: Total revenue from contracts with customers | B13: =SUM(B11:B12) -> 3438.1 | C13: =SUM(C11:C12) -> 3478.37
A14: (b) Contract balances
A15: Trade receivables (refer note 10) | B15: ='Note 6-11'!B47 -> 755.82 | C15: ='Note 6-11'!C47 -> 587.08
A16: Unbilled revenue (refer note 7) | B16: ='Note 6-11'!B19 -> 80.48 | C16: ='Note 6-11'!C19 -> 61.77
A17: Contract liabilities – advance from customers (refer note 19) | B17: ='Note 14-19'!B120 -> 42.39 | C17: ='Note 14-19'!C120 -> 34.744
A19: 21. Other income
A20: Particulars | B20: Year ended March 31, 2026 | C20: Year ended March 31, 2025
A21: Interest income on bank deposits | B21: =-SUMIF(NS_TB_FT27!$H$5:$H$82,"oi.interest_deposits",NS_TB_FT27!$I$5:$I$82)/100000 -> 29.57 | C21: =-SUMIF(NS_TB_FT27!$H$5:$H$82,"oi.interest_deposits",NS_TB_FT27!$J$5:$J$82)/100000 -> 21.25
A22: Miscellaneous income | B22: =-SUMIF(NS_TB_FT27!$H$5:$H$82,"oi.misc",NS_TB_FT27!$I$5:$I$82)/100000 -> 7.72 | C22: =-SUMIF(NS_TB_FT27!$H$5:$H$82,"oi.misc",NS_TB_FT27!$J$5:$J$82)/100000 -> 5.85
A23: Total other income | B23: =SUM(B21:B22) -> 37.29 | C23: =SUM(C21:C22) -> 27.1
A25: 22. Employee benefits expense
A26: Particulars | B26: Year ended March 31, 2026 | C26: Year ended March 31, 2025
A27: Salaries, wages and bonus | B27: =SUMIF(NS_TB_FT27!$H$5:$H$82,"emp.salaries",NS_TB_FT27!$I$5:$I$82)/100000 -> 2432.83 | C27: =SUMIF(NS_TB_FT27!$H$5:$H$82,"emp.salaries",NS_TB_FT27!$J$5:$J$82)/100000 -> 2379.06
A28: Contribution to provident and other funds | B28: =SUMIF(NS_TB_FT27!$H$5:$H$82,"emp.pf",NS_TB_FT27!$I$5:$I$82)/100000 -> 140.12 | C28: =SUMIF(NS_TB_FT27!$H$5:$H$82,"emp.pf",NS_TB_FT27!$J$5:$J$82)/100000 -> 109.64
A29: Gratuity (refer note 16) | B29: =SUMIF(NS_TB_FT27!$H$5:$H$82,"emp.gratuity",NS_TB_FT27!$I$5:$I$82)/100000 -> 39.17 | C29: =SUMIF(NS_TB_FT27!$H$5:$H$82,"emp.gratuity",NS_TB_FT27!$J$5:$J$82)/100000 -> 36.69
A30: Staff welfare expenses | B30: =SUMIF(NS_TB_FT27!$H$5:$H$82,"emp.welfare",NS_TB_FT27!$I$5:$I$82)/100000 -> 32.09 | C30: =SUMIF(NS_TB_FT27!$H$5:$H$82,"emp.welfare",NS_TB_FT27!$J$5:$J$82)/100000 -> 27.58
A31: Total employee benefits expense | B31: =SUM(B27:B30) -> 2644.21 | C31: =SUM(C27:C30) -> 2552.97
A33: 23. Finance costs
A34: Particulars | B34: Year ended March 31, 2026 | C34: Year ended March 31, 2025
A35: Interest on term loan | B35: =SUMIF(NS_TB_FT27!$H$5:$H$82,"fin.interest_bank",NS_TB_FT27!$I$5:$I$82)/100000 -> 25.77 | C35: =SUMIF(NS_TB_FT27!$H$5:$H$82,"fin.interest_bank",NS_TB_FT27!$J$5:$J$82)/100000 -> 35.67
A36: Interest on loan from holding company (refer note 28) | B36: =SUMIF(NS_TB_FT27!$H$5:$H$82,"fin.interest_holding",NS_TB_FT27!$I$5:$I$82)/100000 -> 42.9 | C36: =SUMIF(NS_TB_FT27!$H$5:$H$82,"fin.interest_holding",NS_TB_FT27!$J$5:$J$82)/100000 -> 32.8
A37: Interest on lease liabilities | B37: =SUMIF(NS_TB_FT27!$H$5:$H$82,"fin.interest_lease",NS_TB_FT27!$I$5:$I$82)/100000 -> 16.46 | C37: =SUMIF(NS_TB_FT27!$H$5:$H$82,"fin.interest_lease",NS_TB_FT27!$J$5:$J$82)/100000 -> 21.52
A38: Total finance costs | B38: =SUM(B35:B37) -> 85.13 | C38: =SUM(C35:C37) -> 89.99
A40: 24. Depreciation and amortisation expense
A41: Particulars | B41: Year ended March 31, 2026 | C41: Year ended March 31, 2025
A42: Depreciation on property, plant and equipment (refer note 3) | B42: =SUMIF(NS_TB_FT27!$H$5:$H$82,"dep.ppe",NS_TB_FT27!$I$5:$I$82)/100000 -> 109.56 | C42: =SUMIF(NS_TB_FT27!$H$5:$H$82,"dep.ppe",NS_TB_FT27!$J$5:$J$82)/100000 -> 87.59
A43: Depreciation on right-of-use assets (refer note 4) | B43: =SUMIF(NS_TB_FT27!$H$5:$H$82,"dep.rou",NS_TB_FT27!$I$5:$I$82)/100000 -> 64.53 | C43: =SUMIF(NS_TB_FT27!$H$5:$H$82,"dep.rou",NS_TB_FT27!$J$5:$J$82)/100000 -> 57.73
A44: Amortisation of intangible assets (refer note 5) | B44: =SUMIF(NS_TB_FT27!$H$5:$H$82,"dep.intangibles",NS_TB_FT27!$I$5:$I$82)/100000 -> 21.41 | C44: =SUMIF(NS_TB_FT27!$H$5:$H$82,"dep.intangibles",NS_TB_FT27!$J$5:$J$82)/100000 -> 17.55
A45: Total depreciation and amortisation expense | B45: =SUM(B42:B44) -> 195.5 | C45: =SUM(C42:C44) -> 162.87
...

Sheet RPT
A1: Corvus Data Services Private Limited
A2: Notes to the financial statements for the year ended March 31, 2026
A3: (All amounts in ₹ lakhs, unless otherwise stated)
A5: 28. Related party disclosures
A6: (a) Names of related parties and nature of relationship
A7: Nature of relationship
A8: Holding company and ultimate holding company | B8: Corvus Holdings Private Limited
A9: Fellow subsidiary | B9: Corvus Technologies Inc.
A10: Fellow subsidiary | B10: Corvus Analytics Limited
A11: Fellow subsidiary | B11: Corvus Systems Pte. Ltd.
A12: Setp-down subsidiary of Corvus Holdings Private Limited | B12: Corvus Data Services FZ-LLC
A13: Key managerial personnel | B13: Asha Raman – Director
A14: Key managerial personnel | B14: Vikram Sethi – Director
A15: Key managerial personnel | B15: Neha Kapoor – Chief Financial Officer
A17: (b) Transactions with related parties during the year
A18: Nature of transaction / related party | B18: Year ended March 31, 2026 | C18: Year ended March 31, 2025
A19: Revenue from operations – support services
A20: Corvus Technologies Inc. | B20: =-SUMIF(NS_TB_FT27!$H$5:$H$82,"rev.related_support",NS_TB_FT27!$I$5:$I$82)/100000 -> 1030.27 | C20: =-SUMIF(NS_TB_FT27!$H$5:$H$82,"rev.related_support",NS_TB_FT27!$J$5:$J$82)/100000 -> 748.18
A21: Support services received
A22: Corvus Holdings Private Limited | B22: 527.01 | C22: =SUMIF(NS_TB_FT27!$H$5:$H$82,"oth.support_services_group",NS_TB_FT27!$J$5:$J$82)/100000 -> 482.65
A23: Interest on loan
A24: Corvus Holdings Private Limited | B24: 41.9 | C24: =SUMIF(NS_TB_FT27!$H$5:$H$82,"fin.interest_holding",NS_TB_FT27!$J$5:$J$82)/100000 -> 32.8
A25: Corvus Analytics Limited | B25: 3.45 | C25: 3.45
A26: Loan received
A27: Corvus Holdings Private Limited | B27: 0 | C27: 97.17
A28: Loan repaid
A29: Corvus Holdings Private Limited | B29: 45.2 | C29: 0
A30: Expenses incurred on behalf of the related party (recoverable)
A31: Corvus Analytics Limited | B31: 39.42 | C31: 29.52
A32: Issue of equity shares (including securities premium)
A33: Corvus Holdings Private Limited
A34: Investment in equity shares of subsidiary
A35: Corvus Data Services FZ-LLC | B35: 32.84 | C35: 0
A36: Remuneration to key managerial personnel
A37: Short-term employee benefits – Asha Raman, Vikram Sethi and Neha Kapoor | B37: 104.65 | C37: 96.7
A39: (c) Balance as at June 30, 2026
A40: Nature of balance / related party | B40: As at March 31, 2026 | C40: As at March 31, 2025
A41: Trade payables
A43: Corvus Holdings Pvt. Ltd. | B43: =-SUMIF(NS_TB_FT27!$H$5:$H$82,"tp.related",NS_TB_FT27!$J$5:$J$82)/100000 -> 101.36 | C43: =-SUMIF(NS_TB_FT27!$H$5:$H$82,"tp.related",NS_TB_FT27!$J$5:$J$82)/100000 -> 101.36
A44: Trade receivables
...

Sheet Note 29-34
A1: Corvus Data Services Private Limited
A2: Notes to the financial statements for the year ended March 31, 2026
A3: (All amounts in ₹ lakhs, unless otherwise stated)
A5: 29. Going concern
A6: The Company has earned a profit of ₹ 537.09 lakhs during the year ended March 31, 2026 (previous year: profit of ₹ 186.86 lakhs). As at March 31, 2026, the Company has accumulated losses of ₹ 1,249.53 lakhs and its net worth is ₹ 1,750.27 lakhs (as at March 31, 2025: ₹ 1,250.31 lakhs).
A7: As at June 30, 2026, the current assets of the Company exceed its current liabilities by ₹ 1,615.6 lakhs (as at March 31, 2025: ₹ 697.00 lakhs). As at March 31, 2026, the cash and cash equivalents of the Company amount to ₹ 1,371.98 lakhs (as at March 31, 2025: ₹ 600.91 lakhs).
A8: Management has assessed the Group's ability to continue as a going concern, considering the following mitigating factors:
A9: (a) the holding company, Corvus Holdings Private Limited, infused equity of ₹ 500.00 lakhs during the year ended March 31, 2026;
A10: (b) the holding company has confirmed in writing its continued financial support for a period of at least twelve months from the date of approval of these financial statements; (assessment updated on 31st June, 2026)
A11: (c) the Company has an approved business plan supported by a growing order book from group companies and third-party customers; and
A12: (d) the Company has no overdue borrowings and has met all repayment obligations on time.
A13: Accordingly, these financial statements have been prepared on a going concern basis and do not include any adjustments that might result if the Company were unable to continue as a going concern.
A15: 30. Additional regulatory information – ratios
A16: Ratio | B16: Numerator | C16: Denominator | D16: Current year | E16: Previous year | F16: % variance | G16: Reason for variance (where > 25%)
A17: Current ratio (times) | B17: Current assets | C17: Current liabilities | D17: =BS!C24/BS!C50 -> 3.1676864 | E17: 2.016 | F17: =IF(E17=0,0,(D17-E17)/ABS(E17)) -> 0.571273 | G17: The increase is mainly on account of the movement in current assets during the year.
A18: Debt-equity ratio (times) | B18: Total debt (borrowings and lease liabilities) | C18: Total equity | D18: =(BS!C35+BS!C41+BS!C36+BS!C42)/BS!C31 -> 0.58260537 | E18: 1.2804 | F18: =IF(E18=0,0,(D18-E18)/ABS(E18)) -> -0.54498175 | G18: The decrease is mainly on account of the movement in total debt (borrowings and lease liabilities) during the year.
A19: Debt service coverage ratio (times) | B19: Earnings available for debt service (profit after tax + depreciation + finance costs) | C19: Debt service (interest, lease payments and principal repayments) | D19: =(PL!C20+PL!C12+PL!C11)/-(CFS!B40+CFS!B38+CFS!B39+CFS!B37) -> 3.6863845 | E19: 0.2943 | F19: =IF(E19=0,0,(D19-E19)/ABS(E19)) -> 11.525941 | G19: The increase is mainly on account of the movement in earnings available for debt service (profit after tax + depreciation + finance costs) during the year.
A20: Return on equity (%) | B20: Profit after tax | C20: Average total equity | D20: =PL!C20/((BS!C31+BS!D31)/2/2) -> 0.63360239 | E20: -0.2129 | F20: =IF(E20=0,0,(D20-E20)/ABS(E20)) -> 3.9760563 | G20: The increase is mainly on account of the movement in profit after tax during the year.
A21: Trade receivables turnover ratio (times) | B21: Revenue from operations | C21: Average trade receivables | D21: =PL!C6/((BS!C20+BS!D20)/2) -> 6.6548068 | E21: 4.5015 | F21: =IF(E21=0,0,(D21-E21)/ABS(E21)) -> 0.47835316 | G21: The increase is mainly on account of the movement in revenue from operations during the year.
A22: Trade payables turnover ratio (times) | B22: Other expenses | C22: Average trade payables | D22: =PL!C13/((BS!C44+BS!C45+BS!D44+BS!D45)/2) -> 3.4657878 | E22: 3.2122 | F22: =IF(E22=0,0,(D22-E22)/ABS(E22)) -> 0.078945198 | G22: -
A23: Net capital turnover ratio (times) | B23: Revenue from operations | C23: Average working capital | D23: =PL!C6/(((BS!C24-BS!C50)+(BS!D24-BS!D50))/2) -> 3.8643323 | E23: 4.3513 | F23: =IF(E23=0,0,(D23-E23)/ABS(E23)) -> -0.11191314 | G23: -
A24: Net profit ratio (%) | B24: Profit after tax | C24: Revenue from operations | D24: =PL!C20/PL!C6 -> 0.10636988 | E24: -0.0537 | F24: =IF(E24=0,0,(D24-E24)/ABS(E24)) -> 2.9808172 | G24: -
A25: Return on capital employed (%) | B25: Earnings before interest and tax | C25: Capital employed (total equity + total debt) | D25: =(PL!C15)/(BS!C31+(BS!C35+BS!C41+BS!C36+BS!C42)) -> 0.23377917 | E25: -0.0569 | F25: =IF(E25=0,0,(D25-E25)/ABS(E25)) -> 5.1085971 | G25: The increase is mainly on account of the movement in earnings before interest and tax during the year.
A26: Inventory turnover ratio and return on investment are not applicable as the Company is a service company and holds no treasury investments.
A28: 31. Contingent liabilities and commitments
A29: Particulars | B29: As at March 31, 2026 | C29: As at March 31, 2025
A30: (a) Contingent liabilities (claims against the Company not acknowledged as debts)
A31: Income-tax demands under appeal | B31: 13.4 | C31: 12.26
A32: Indirect tax matters under dispute | B32: 5.95 | C32: 6.43
A33: Total | B33: =SUM(B31:B32) -> 19.35 | C33: =SUM(C31:C32) -> 18.69
A34: (b) Commitments
A35: Estimated amount of contracts remaining to be executed on capital account (net of advances) | B35: 3.54 | C35: 3.07
A37: 32. Financial instruments
A38: Particulars | B38: As at March 31, 2026 | C38: As at March 31, 2025
A39: (a) Categories of financial instruments – measured at amortised cost
A40: Financial assets
A41: Trade receivables | B41: ='Note 6-11'!B47 -> 755.82 | C41: ='Note 6-11'!C47 -> 587.08
A42: Cash and cash equivalents | B42: ='Note 6-11'!B65 -> 1371.98 | C42: ='Note 6-11'!C65 -> 600.91
A43: Other financial assets (non-current and current) | B43: ='Note 6-11'!B16+'Note 6-11'!B21 -> 165.35 | C43: ='Note 6-11'!C16+'Note 6-11'!C21 -> 133.82
A44: Total financial assets | B44: =SUM(B41:B43) -> 2293.15 | C44: =SUM(C41:C43) -> 1321.81
...

Sheet NS_TB_FT27
A1: Corvus Data Services Private Limited
A2: Trial balance – saved search FT27 (amounts in INR)
A4: Account No | B4: Account Name | C4: Level 1 | D4: Level 2 | E4: Level 3 | F4: Level 4 | G4: Level 5 | H4: FS Grouping | I4: Mar-26 | J4: Mar-25
A5: 11010 | B5: Computers - Gross | C5: Assets | D5: Non Current Assets | E5: Property Plant and Equipment | F5: Computers | G5: Computers - Gross | H5: ppe.gross.computers | I5: 64609000 | J5: 52377000
A6: 11020 | B6: Furniture and Fixtures - Gross | C6: Assets | D6: Non Current Assets | E6: Property Plant and Equipment | F6: Furniture | G6: Furniture and Fixtures - Gross | H6: ppe.gross.furniture | I6: 20939000 | J6: 18171000
A7: 11030 | B7: Office Equipment - Gross | C7: Assets | D7: Non Current Assets | E7: Property Plant and Equipment | F7: Office Equipment | G7: Office Equipment - Gross | H7: ppe.gross.office_equipment | I7: 13124000 | J7: 11178000
A8: 11110 | B8: Accumulated Depreciation - Computers | C8: Assets | D8: Non Current Assets | E8: Property Plant and Equipment | F8: Computers | G8: Accumulated Depreciation - Computers | H8: ppe.accdep.computers | I8: -31327000 | J8: -24049000
A9: 11120 | B9: Accumulated Depreciation - Furniture | C9: Assets | D9: Non Current Assets | E9: Property Plant and Equipment | F9: Furniture | G9: Accumulated Depreciation - Furniture | H9: ppe.accdep.furniture | I9: -5962000 | J9: -5475000
A10: 11130 | B10: Accumulated Depreciation - Office Equipment | C10: Assets | D10: Non Current Assets | E10: Property Plant and Equipment | F10: Office Equipment | G10: Accumulated Depreciation - Office Equipment | H10: ppe.accdep.office_equipment | I10: -5603000 | J10: -4388000
A11: 11500 | B11: Capital Work in Progress | C11: Assets | D11: Non Current Assets | E11: Capital Work in Progress | F11: Capital Work in Progress | G11: Capital Work in Progress | H11: cwip | I11: 1086000 | J11: 857000
A12: 11600 | B12: Right of Use Asset - Office Premises | C12: Assets | D12: Non Current Assets | E12: Right of Use Assets | F12: Right of Use Asset - Office Premises | G12: Right of Use Asset - Office Premises | H12: rou.gross.buildings | I12: 40333000 | J12: 36080000
A13: 11610 | B13: Accumulated Depreciation - ROU Asset | C13: Assets | D13: Non Current Assets | E13: Right of Use Assets | F13: Accumulated Depreciation - ROU Asset | G13: Accumulated Depreciation - ROU Asset | H13: rou.accdep.buildings | I13: -22561000 | J13: -16108000
A14: 11700 | B14: Software Licences - Gross | C14: Assets | D14: Non Current Assets | E14: Intangible Assets | F14: Software Licences - Gross | G14: Software Licences - Gross | H14: intangibles.gross.software | I14: 11894000 | J14: 9750000
A15: 11710 | B15: Accumulated Amortisation - Software | C15: Assets | D15: Non Current Assets | E15: Intangible Assets | F15: Accumulated Amortisation - Software | G15: Accumulated Amortisation - Software | H15: intangibles.accamort.software | I15: -6509000 | J15: -4368000
A16: 12000 | B16: Investment in Subsidiary - Equity Shares | C16: Assets | D16: Non Current Assets | E16: Investments | F16: Investment in Subsidiary - Equity Shares | G16: Investment in Subsidiary - Equity Shares | H16: inv.nc.subsidiary | I16: 28284000 | J16: 25000000
... A82: 55010 | B82: Tax on OCI Items | C82: Expenses | D82: Other Comprehensive Income | E82: Tax on OCI | F82: Tax on OCI Items | G82: Tax on OCI Items | H82: oci.tax | I82: -246000 | J82: -164000
B83: Total | I83: =SUM(I5:I82) -> 0 | J83: =SUM(J5:J82) -> 0

Sheet FAR
A1: Corvus Data Services Private Limited
A2: Fixed asset register – summary by class (amounts in INR)
A4: Asset class | B4: Opening gross block | C4: Additions (incl. CWIP capitalised) | D4: Disposals | E4: Closing gross block | F4: Opening accumulated depreciation | G4: Charge for the year | H4: Depreciation on disposals | I4: Closing accumulated depreciation | J4: Net block
A5: Financial year ended March 31, 2025
A6: Computers | B6: 39780000 | C6: 14188000 | D6: 1591000 | E6: =B6+C6-D6 -> 52377000 | F6: 18306000 | G6: 6857000 | H6: 1114000 | I6: =F6+G6-H6 -> 24049000 | J6: =E6-I6 -> 28328000
A7: Furniture and fixtures | B7: 16115000 | C7: 2701000 | D7: 645000 | E7: =B7+C7-D7 -> 18171000 | F7: 5054000 | G7: 873000 | H7: 452000 | I7: =F7+G7-H7 -> 5475000 | J7: =E7-I7 -> 12696000
A8: Office equipment | B8: 9408000 | C8: 1770000 | D8: 0 | E8: =B8+C8-D8 -> 11178000 | F8: 3359000 | G8: 1029000 | H8: 0 | I8: =F8+G8-H8 -> 4388000 | J8: =E8-I8 -> 6790000
A9: Total | B9: =SUM(B6:B8) -> 65303000 | C9: =SUM(C6:C8) -> 18659000 | D9: =SUM(D6:D8) -> 2236000 | E9: =SUM(E6:E8) -> 81726000 | F9: =SUM(F6:F8) -> 26719000 | G9: =SUM(G6:G8) -> 8759000 | H9: =SUM(H6:H8) -> 1566000 | I9: =SUM(I6:I8) -> 33912000 | J9: =SUM(J6:J8) -> 47814000
A11: Financial year ended March 31, 2026
A12: Computers | B12: =E6 -> 52377000 | C12: 14327000 | D12: 2095000 | E12: =B12+C12-D12 -> 64609000 | F12: =I6 -> 24049000 | G12: 8745000 | H12: 1467000 | I12: =F12+G12-H12 -> 31327000 | J12: =E12-I12 -> 33282000
A13: Furniture and fixtures | B13: =E7 -> 18171000 | C13: 3495000 | D13: 727000 | E13: =B13+C13-D13 -> 20939000 | F13: =I7 -> 5475000 | G13: 996000 | H13: 509000 | I13: =F13+G13-H13 -> 5962000 | J13: =E13-I13 -> 14977000
A14: Office equipment | B14: =E8 -> 11178000 | C14: 1946000 | D14: 0 | E14: =B14+C14-D14 -> 13124000 | F14: =I8 -> 4388000 | G14: 1215000 | H14: 0 | I14: =F14+G14-H14 -> 5603000 | J14: =E14-I14 -> 7521000
A15: Total | B15: =SUM(B12:B14) -> 81726000 | C15: =SUM(C12:C14) -> 19768000 | D15: =SUM(D12:D14) -> 2822000 | E15: =SUM(E12:E14) -> 98672000 | F15: =SUM(F12:F14) -> 33912000 | G15: =SUM(G12:G14) -> 10956000 | H15: =SUM(H12:H14) -> 1976000 | I15: =SUM(I12:I14) -> 42892000 | J15: =SUM(J12:J14) -> 55780000
A17: Right-of-use assets – buildings
A18: FY ended March 31, 2025 | B18: 36080000 | C18: 0 | D18: 0 | E18: =B18+C18-D18 -> 36080000 | F18: 10335000 | G18: 5773000 | H18: 0 | I18: =F18+G18-H18 -> 16108000 | J18: =E18-I18 -> 19972000
A19: FY ended March 31, 2026 | B19: =E18 -> 36080000 | C19: 4253000 | D19: 0 | E19: =B19+C19-D19 -> 40333000 | F19: =I18 -> 16108000 | G19: 6453000 | H19: 0 | I19: =F19+G19-H19 -> 22561000 | J19: =E19-I19 -> 17772000
A21: Computer software
A22: FY ended March 31, 2025 | B22: 7841000 | C22: 1909000 | D22: 0 | E22: =B22+C22-D22 -> 9750000 | F22: 2613000 | G22: 1755000 | H22: 0 | I22: =F22+G22-H22 -> 4368000 | J22: =E22-I22 -> 5382000
A23: FY ended March 31, 2026 | B23: =E22 -> 9750000 | C23: 2144000 | D23: 0 | E23: =B23+C23-D23 -> 11894000 | F23: =I22 -> 4368000 | G23: 2141000 | H23: 0 | I23: =F23+G23-H23 -> 6509000 | J23: =E23-I23 -> 5385000
A25: Capital work-in-progress (opening / additions / capitalised / closing)
A26: FY ended March 31, 2025 | B26: 1041000 | C26: 2142000 | D26: 2326000 | E26: =B26+C26-D26 -> 857000
A27: FY ended March 31, 2026 | B27: =E26 -> 857000 | C27: 2715000 | D27: 2486000 | E27: =B27+C27-D27 -> 1086000

Sheet Ageing
A1: Corvus Data Services Private Limited
A2: Receivables and payables ageing (amounts in INR)
A4: Trade receivables | B4: Not due | C4: Less than 6 months | D4: 6 months - 1 year | E4: 1-2 years | F4: 2-3 years | G4: More than 3 years | H4: Total
A5: As at March 31, 2026
A6: Undisputed – considered good | B6: 39257000 | C6: 23528000 | D6: 6795000 | E6: 3775000 | F6: 1510000 | G6: 755000 | H6: =SUM(B6:G6) -> 75620000
A7: Undisputed – credit impaired | B7: 0 | C7: 0 | D7: 0 | E7: 0 | F7: 0 | G7: 3308000 | H7: =SUM(B7:G7) -> 3308000
A8: Total | B8: =SUM(B6:B7) -> 39257000 | C8: =SUM(C6:C7) -> 23528000 | D8: =SUM(D6:D7) -> 6795000 | E8: =SUM(E6:E7) -> 3775000 | F8: =SUM(F6:F7) -> 1510000 | G8: =SUM(G6:G7) -> 4063000 | H8: =SUM(H6:H7) -> 78928000
A10: As at March 31, 2025
A11: Undisputed – considered good | B11: 30483000 | C11: 18173000 | D11: 5276000 | E11: 2931000 | F11: 1172000 | G11: 586000 | H11: =SUM(B11:G11) -> 58621000
A12: Undisputed – credit impaired | B12: 0 | C12: 0 | D12: 0 | E12: 0 | F12: 0 | G12: 2438000 | H12: =SUM(B12:G12) -> 2438000
A13: Total | B13: =SUM(B11:B12) -> 30483000 | C13: =SUM(C11:C12) -> 18173000 | D13: =SUM(D11:D12) -> 5276000 | E13: =SUM(E11:E12) -> 2931000 | F13: =SUM(F11:F12) -> 1172000 | G13: =SUM(G11:G12) -> 3024000 | H13: =SUM(H11:H12) -> 61059000
A15: Trade payables | B15: Not due | C15: Less than 1 year | D15: 1-2 years | E15: 2-3 years | F15: More than 3 years | G15: Total
A16: As at March 31, 2026
A17: MSME | B17: 1279000 | C17: 548000 | D17: 0 | E17: 0 | F17: 0 | G17: =SUM(B17:F17) -> 1827000
A18: Others | B18: 15312000 | C18: 7656000 | D18: 2552000 | E18: 0 | F18: 0 | G18: =SUM(B18:F18) -> 25520000
A19: Total | B19: =SUM(B17:B18) -> 16591000 | C19: =SUM(C17:C18) -> 8204000 | D19: =SUM(D17:D18) -> 2552000 | E19: =SUM(E17:E18) -> 0 | F19: =SUM(F17:F18) -> 0 | G19: =SUM(G17:G18) -> 27347000
A21: As at March 31, 2025
A22: MSME | B22: 1367000 | C22: 586000 | D22: 0 | E22: 0 | F22: 0 | G22: =SUM(B22:F22) -> 1953000
A23: Others | B23: 14733000 | C23: 7367000 | D23: 2455000 | E23: 0 | F23: 0 | G23: =SUM(B23:F23) -> 24555000
A24: Total | B24: =SUM(B22:B23) -> 16100000 | C24: =SUM(C22:C23) -> 7953000 | D24: =SUM(D22:D23) -> 2455000 | E24: =SUM(E22:E23) -> 0 | F24: =SUM(F22:F23) -> 0 | G24: =SUM(G22:G23) -> 26508000
